Workbook

Sheet АвтоРасчёт 
A1: Наименование отряда | B1: № | C1: Раса | D1: Тип отряда | E1: Вид брони | F1: Оружие | G1: Есть ли два оружия в руках? | H1: Оружие ББ (в руке) | I1: АрмРанг | J1: Скорость | K1: Дальность | L1: Мощность | M1: Свойства | N1: ББ | O1: Броня | P1: АрмРанг ЦЕНА | Q1: Оружие ЦЕНА | R1: ББ ЦЕНА | S1: Свойства ЦЕНА | T1: Броня / скорость ЦЕНА | U1: Раса ЦЕНА | V1: Цена бойца | W1: Цена отряда | X1: Цена отряда | Y1: Тяжёлое вооружение
A2: Исходная таблица | B2: 1 | F2: (нет) | H2: Без оружия | I2: =IF(D2="Элитный тяжёлый отряд",IF(C2="Клон",4,$E$17),IF(D2="Спецназ",IF(C2="Клон",3,$E$18),IF(D2="Ударное подразделение",IF(C2="Клон",2,$E$19),IF(D2="Основное подразделение",$E$20,IF(D2="Ополчение/Полиция",$E$21,""))))) | J2: =IF(E2="Одежда",IF($Y$8<=2, $G$24,4),IF(E2="Шлем, лёгкая кирасса",IF($Y$8<=2, $G$25,4),IF(E2="Тяжёлая кирасса, напленики",IF($Y$8<=2, $G$26,4),IF(E2="Киборг",IF($Y$8<=2, $G$27,4),IF(E2="Шлем, лёгкая кирасса, щит",IF($Y$8<=2, $G$28,3),IF(E2="Тяжёлый пехотный доспех",IF($Y$8<=2, $G$29,3),IF(E2="Фелицианский лёгкий бронекостюм",IF($Y$8<=2, $G$30,5),IF(E2="Киборг в лёгкой броне",IF($Y$8<=2, $G$31,3),IF(E2="Бронекостюм",IF($Y$8<=2, $G$32,3),IF(E2="Киборг в тяжёлой броне",IF($Y$8<=2, $G$33,3),IF(E2="Экзоскилет",$G$34,""))))))))))) | K2: =IF(F2="Пистолет",IF(+G2= "Да",$M$37,$G$37),IF(F2="Пистолет-пулемёт",IF(+G2= "Да",$M$37,$G$38),IF(F2="Дробовик",$G$39,IF(F2="Автомат",$G$40,IF(F2="Штурмовой карабин",$G$41,IF(F2="Снайперская Винтовка",$G$42,IF(F2="Пулемёт",$G$43,IF(F2="Гранатомёт/ракетница",$G$44,IF(F2="Противотанокое ружьё",$G$45,IF(F2="Огнемёт",$G$46,IF(F2="ЛазПистолет",IF(+G2= "Да",$M$38, $G$47),IF(F2="ЛазГан",$G$48,IF(F2="ЛазПушка",$G$49,IF(F2="ПлазПистолет ",IF(+G2= "Да",$M$37, $G$50),IF(F2="ПлазГан",$G$51,IF(F2="ПлазПушка",$G$52,IF(F2="Глюонный пистолет",IF(+G2= "Да",$M$37, $G$53),IF(F2="Глюонная винтовка",$G$54,IF(F2="Глюонная пушка",$G$55,""))))))))))))))))))) | L2: =IF(F2="Пистолет",IF(+G2= "Да",$N$37, $H$37),IF(F2="Пистолет-пулемёт",IF(+G2= "Да",$N$38, $H$38),IF(F2="Дробовик",$H$39,IF(F2="Автомат",$H$40,IF(F2="Штурмовой карабин",$H$41,IF(F2="Снайперская Винтовка",$H$42,IF(F2="Пулемёт",$H$43,IF(F2="Гранатомёт/ракетница",$H$44,IF(F2="Противотанокое ружьё",$H$45,IF(F2="Огнемёт",$H$46,IF(F2="ЛазПистолет",IF(+G2= "Да",$N$39, $H$47),IF(F2="ЛазГан",$H$48,IF(F2="ЛазПушка",$H$49,IF(F2="ПлазПистолет ",IF(+G2= "Да",$N$40, $H$50),IF(F2="ПлазГан",$H$51,IF(F2="ПлазПушка",$H$52,IF(F2="Глюонный пистолет",IF(+G2= "Да",$N$41, $H$53),IF(F2="Глюонная винтовка",$H$54,IF(F2="Глюонная пушка",$H$55,""))))))))))))))))))) | M2: (нет) | N2: =IF(H2="Без оружия",IF(C2="Мутант",4,IF(E2="Экзоскилет",3,IF(D2="Элитный тяжёлый отряд",3,IF(D2="Спецназ",3,IF(C2="Клон",3,$I$64))))),IF(H2="Нож",IF(C2="Мутант",4,IF(E2="Экзоскилет",4,IF(D2="Элитный тяжёлый отряд",4,IF(D2="Спецназ",4,IF(C2="Клон",3,$I$65))))),IF(H2="Холодное оружие",IF(C2="Мутант",6,IF(E2="Экзоскилет",5,IF(D2="Элитный тяжёлый отряд",5,IF(D2="Спецназ",5,IF(C2="Клон",5,$I$66))))),IF(H2="Пило/Электро",IF(C2="Мутант",7,IF(E2="Экзоскилет",6,IF(D2="Элитный тяжёлый отряд",6,IF(D2="Спецназ",7,IF(C2="Клон",6,$I$67))))),IF(H2="Двуручное оружие ББ",IF(E2="Экзоскилет",7,IF(D2="Элитный тяжёлый отряд",7,IF(D2="Спецназ",7,IF(C2="Клон",7,IF(C2="Мутант",7,$I$68))))),IF(H2="Тяжёлое стрелковое",IF(E2="Экзоскилет",3,$I$69),"")))))) -> 2 | O2: =IF(E2="Одежда",IF(C2="Мутант",3,$F$24),IF(E2="Шлем, лёгкая кирасса",IF(C2="Мутант",4,$F$25),IF(E2="Тяжёлая кирасса, напленики",IF(C2="Мутант",5,$F$26),IF(E2="Киборг",$F$27,IF(E2="Шлем, лёгкая кирасса, щит",IF(C2="Мутант",6,$F$28),IF(E2="Тяжёлый пехотный доспех",IF(C2="Мутант",6,$F$29),IF(E2="Фелицианский лёгкий бронекостюм",$F$30,IF(E2="Киборг в лёгкой броне",$F$31,IF(E2="Бронекостюм",IF(C2="Мутант",6,$F$32),IF(E2="Киборг в тяжёлой броне",$F$33,IF(E2="Экзоскилет",$F$34,""))))))))))) | P2: =IF(D2="Элитный тяжёлый отряд",$F$17,IF(D2="Спецназ",$F$18,IF(D2="Ударное подразделение",$F$19,IF(D2="Основное подразделение",$F$20,IF(D2="Ополчение/Полиция",$F$21,""))))) | Q2: =IF(F2="Пистолет", $K$37,IF(F2="Пистолет-пулемёт",$K$38,IF(F2="Дробовик",$K$39,IF(F2="Автомат",$K$40,IF(F2="Штурмовой карабин",$K$41,IF(F2="Снайперская Винтовка",$K$42,IF(F2="Пулемёт",$K$43,IF(F2="Гранатомёт/ракетница",$K$44,IF(F2="Противотанокое ружьё",$K$45,IF(F2="Огнемёт",$K$46,IF(F2="ЛазПистолет",$K$47,IF(F2="ЛазГан",$K$48,IF(F2="ЛазПушка",$K$49,IF(F2="ПлазПистолет ",$K$50,IF(F2="ПлазГан",$K$51,IF(F2="ПлазПушка",$K$52,IF(F2="Глюонный пистолет",$K$53,IF(F2="Глюонная винтовка",$K$54,IF(F2="Глюонная пушка",$K$55,""))))))))))))))))))) | R2: =IF(H2="Без оружия",$J$64,IF(H2="Нож",$J$65,IF(H2="Холодное оружие",$J$66,IF(H2="Пило/Электро",$J$67,IF(H2="Двуручное оружие ББ",$J$68,IF(H2="Тяжёлое стрелковое",$J$69,"")))))) -> 0 | S2: =IF(M2="(нет)",$N$15,IF(M2="Рм",$N$11,IF(M2="Пр3",$N$12,IF(M2="Пр4",$N$13,IF(M2="Пр5",$N$14,""))))) -> 0 | T2: =IF(E2="Одежда",$H$24,IF(E2="Шлем, лёгкая кирасса",$H$25,IF(E2="Тяжёлая кирасса, напленики",$H$26,IF(E2="Киборг",$H$27,IF(E2="Шлем, лёгкая кирасса, щит",$H$28,IF(E2="Тяжёлый пехотный доспех",$H$29,IF(E2="Фелицианский лёгкий бронекостюм",$H$30,IF(E2="Киборг в лёгкой броне",$H$31,IF(E2="Бронекостюм",$H$32,IF(E2="Киборг в тяжёлой броне",$H$33,IF(E2="Экзоскилет",$H$34,""))))))))))) | U2: =IF(C2="Человек",$H$11,IF(C2="Клон",$H$12,IF(C2="Киборг",$H$13,IF(C2="Мутант",$H$14,"")))) | V2: =SUM(P2:U2) -> 0 | W2: =SUM(V2:V7)/10 -> 1 | X2: =_xlfn.CEILING.PRECISE(W2,5) -> 5 | Y2: =IF(F2="Пистолет",0,IF(F2="Пистолет-пулемёт",0,IF(F2="Дробовик",0,IF(F2="Автомат",0,IF(F2="Штурмовой карабин",0,IF(F2="Снайперская Винтовка",1,IF(F2="Пулемёт",1,IF(F2="Гранатомёт/ракетница",1,IF(F2="Противотанокое ружьё",1,IF(F2="Огнемёт",1,IF(F2="ЛазПистолет",0,IF(F2="ЛазГан",0,IF(F2="ЛазПушка",1,IF(F2="ПлазПистолет ",0,IF(F2="ПлазГан",0,IF(F2="ПлазПушка",1,IF(F2="Глюонный пистолет",0,IF(F2="Глюонная винтовка",0,IF(F2="Глюонная пушка",1,"")))))))))))))))))))
B3: 2 | F3: (нет) | H3: Без оружия | I3: =IF(D3="Элитный тяжёлый отряд",IF(C3="Клон",4,$E$17),IF(D3="Спецназ",IF(C3="Клон",3,$E$18),IF(D3="Ударное подразделение",IF(C3="Клон",2,$E$19),IF(D3="Основное подразделение",$E$20,IF(D3="Ополчение/Полиция",$E$21,""))))) | J3: =IF(E3="Одежда",IF($Y$8<=2, $G$24,4),IF(E3="Шлем, лёгкая кирасса",IF($Y$8<=2, $G$25,4),IF(E3="Тяжёлая кирасса, напленики",IF($Y$8<=2, $G$26,4),IF(E3="Киборг",IF($Y$8<=2, $G$27,4),IF(E3="Шлем, лёгкая кирасса, щит",IF($Y$8<=2, $G$28,3),IF(E3="Тяжёлый пехотный доспех",IF($Y$8<=2, $G$29,3),IF(E3="Фелицианский лёгкий бронекостюм",IF($Y$8<=2, $G$30,5),IF(E3="Киборг в лёгкой броне",IF($Y$8<=2, $G$31,3),IF(E3="Бронекостюм",IF($Y$8<=2, $G$32,3),IF(E3="Киборг в тяжёлой броне",IF($Y$8<=2, $G$33,3),IF(E3="Экзоскилет",$G$34,""))))))))))) | K3: =IF(F3="Пистолет",IF(+G3= "Да",$M$37,$G$37),IF(F3="Пистолет-пулемёт",IF(+G3= "Да",$M$37,$G$38),IF(F3="Дробовик",$G$39,IF(F3="Автомат",$G$40,IF(F3="Штурмовой карабин",$G$41,IF(F3="Снайперская Винтовка",$G$42,IF(F3="Пулемёт",$G$43,IF(F3="Гранатомёт/ракетница",$G$44,IF(F3="Противотанокое ружьё",$G$45,IF(F3="Огнемёт",$G$46,IF(F3="ЛазПистолет",IF(+G3= "Да",$M$38, $G$47),IF(F3="ЛазГан",$G$48,IF(F3="ЛазПушка",$G$49,IF(F3="ПлазПистолет ",IF(+G3= "Да",$M$37, $G$50),IF(F3="ПлазГан",$G$51,IF(F3="ПлазПушка",$G$52,IF(F3="Глюонный пистолет",IF(+G3= "Да",$M$37, $G$53),IF(F3="Глюонная винтовка",$G$54,IF(F3="Глюонная пушка",$G$55,""))))))))))))))))))) | L3: =IF(F3="Пистолет",IF(+G3= "Да",$N$37, $H$37),IF(F3="Пистолет-пулемёт",IF(+G3= "Да",$N$38, $H$38),IF(F3="Дробовик",$H$39,IF(F3="Автомат",$H$40,IF(F3="Штурмовой карабин",$H$41,IF(F3="Снайперская Винтовка",$H$42,IF(F3="Пулемёт",$H$43,IF(F3="Гранатомёт/ракетница",$H$44,IF(F3="Противотанокое ружьё",$H$45,IF(F3="Огнемёт",$H$46,IF(F3="ЛазПистолет",IF(+G3= "Да",$N$39, $H$47),IF(F3="ЛазГан",$H$48,IF(F3="ЛазПушка",$H$49,IF(F3="ПлазПистолет ",IF(+G3= "Да",$N$40, $H$50),IF(F3="ПлазГан",$H$51,IF(F3="ПлазПушка",$H$52,IF(F3="Глюонный пистолет",IF(+G3= "Да",$N$41, $H$53),IF(F3="Глюонная винтовка",$H$54,IF(F3="Глюонная пушка",$H$55,""))))))))))))))))))) | M3: (нет) | N3: =IF(H3="Без оружия",IF(C3="Мутант",4,IF(E3="Экзоскилет",3,IF(D3="Элитный тяжёлый отряд",3,IF(D3="Спецназ",3,IF(C3="Клон",3,$I$64))))),IF(H3="Нож",IF(C3="Мутант",4,IF(E3="Экзоскилет",4,IF(D3="Элитный тяжёлый отряд",4,IF(D3="Спецназ",4,IF(C3="Клон",3,$I$65))))),IF(H3="Холодное оружие",IF(C3="Мутант",6,IF(E3="Экзоскилет",5,IF(D3="Элитный тяжёлый отряд",5,IF(D3="Спецназ",5,IF(C3="Клон",5,$I$66))))),IF(H3="Пило/Электро",IF(C3="Мутант",7,IF(E3="Экзоскилет",6,IF(D3="Элитный тяжёлый отряд",6,IF(D3="Спецназ",7,IF(C3="Клон",6,$I$67))))),IF(H3="Двуручное оружие ББ",IF(E3="Экзоскилет",7,IF(D3="Элитный тяжёлый отряд",7,IF(D3="Спецназ",7,IF(C3="Клон",7,IF(C3="Мутант",7,$I$68))))),IF(H3="Тяжёлое стрелковое",IF(E3="Экзоскилет",3,$I$69),"")))))) -> 2 | O3: =IF(E3="Одежда",IF(C3="Мутант",3,$F$24),IF(E3="Шлем, лёгкая кирасса",IF(C3="Мутант",4,$F$25),IF(E3="Тяжёлая кирасса, напленики",IF(C3="Мутант",5,$F$26),IF(E3="Киборг",$F$27,IF(E3="Шлем, лёгкая кирасса, щит",IF(C3="Мутант",6,$F$28),IF(E3="Тяжёлый пехотный доспех",IF(C3="Мутант",6,$F$29),IF(E3="Фелицианский лёгкий бронекостюм",$F$30,IF(E3="Киборг в лёгкой броне",$F$31,IF(E3="Бронекостюм",IF(C3="Мутант",6,$F$32),IF(E3="Киборг в тяжёлой броне",$F$33,IF(E3="Экзоскилет",$F$34,""))))))))))) | P3: =IF(D3="Элитный тяжёлый отряд",$F$17,IF(D3="Спецназ",$F$18,IF(D3="Ударное подразделение",$F$19,IF(D3="Основное подразделение",$F$20,IF(D3="Ополчение/Полиция",$F$21,""))))) | Q3: =IF(F3="Пистолет",$K$37,IF(F3="Пистолет-пулемёт",$K$38,IF(F3="Дробовик",$K$39,IF(F3="Автомат",$K$40,IF(F3="Штурмовой карабин",$K$41,IF(F3="Снайперская Винтовка",$K$42,IF(F3="Пулемёт",$K$43,IF(F3="Гранатомёт/ракетница",$K$44,IF(F3="Противотанокое ружьё",$K$45,IF(F3="Огнемёт",$K$46,IF(F3="ЛазПистолет",$K$47,IF(F3="ЛазГан",$K$48,IF(F3="ЛазПушка",$K$49,IF(F3="ПлазПистолет ",$K$50,IF(F3="ПлазГан",$K$51,IF(F3="ПлазПушка",$K$52,IF(F3="Глюонный пистолет",$K$53,IF(F3="Глюонная винтовка",$K$54,IF(F3="Глюонная пушка",$K$55,""))))))))))))))))))) | R3: =IF(H3="Без оружия",$J$64,IF(H3="Нож",$J$65,IF(H3="Холодное оружие",$J$66,IF(H3="Пило/Электро",$J$67,IF(H3="Двуручное оружие ББ",$J$68,IF(H3="Тяжёлое стрелковое",$J$69,"")))))) -> 0 | S3: =IF(M3="(нет)",$N$15,IF(M3="Рм",$N$11,IF(M3="Пр3",$N$12,IF(M3="Пр4",$N$13,IF(M3="Пр5",$N$14,""))))) -> 0 | T3: =IF(E3="Одежда",$H$24,IF(E3="Шлем, лёгкая кирасса",$H$25,IF(E3="Тяжёлая кирасса, напленики",$H$26,IF(E3="Киборг",$H$27,IF(E3="Шлем, лёгкая кирасса, щит",$H$28,IF(E3="Тяжёлый пехотный доспех",$H$29,IF(E3="Фелицианский лёгкий бронекостюм",$H$30,IF(E3="Киборг в лёгкой броне",$H$31,IF(E3="Бронекостюм",$H$32,IF(E3="Киборг в тяжёлой броне",$H$33,IF(E3="Экзоскилет",$H$34,""))))))))))) | U3: =IF(C3="Человек",$H$11,IF(C3="Клон",$H$12,IF(C3="Киборг",$H$13,IF(C3="Мутант",$H$14,"")))) | V3: =SUM(P3:U3) -> 0 | Y3: =IF(F3="Пистолет",0,IF(F3="Пистолет-пулемёт",0,IF(F3="Дробовик",0,IF(F3="Автомат",0,IF(F3="Штурмовой карабин",0,IF(F3="Снайперская Винтовка",1,IF(F3="Пулемёт",1,IF(F3="Гранатомёт/ракетница",1,IF(F3="Противотанокое ружьё",1,IF(F3="Огнемёт",1,IF(F3="ЛазПистолет",0,IF(F3="ЛазГан",0,IF(F3="ЛазПушка",1,IF(F3="ПлазПистолет ",0,IF(F3="ПлазГан",0,IF(F3="ПлазПушка",1,IF(F3="Глюонный пистолет",0,IF(F3="Глюонная винтовка",0,IF(F3="Глюонная пушка",1,"")))))))))))))))))))
B4: 3 | F4: (нет) | H4: Без оружия | I4: =IF(D4="Элитный тяжёлый отряд",IF(C4="Клон",4,$E$17),IF(D4="Спецназ",IF(C4="Клон",3,$E$18),IF(D4="Ударное подразделение",IF(C4="Клон",2,$E$19),IF(D4="Основное подразделение",$E$20,IF(D4="Ополчение/Полиция",$E$21,""))))) | J4: =IF(E4="Одежда",IF($Y$8<=2, $G$24,4),IF(E4="Шлем, лёгкая кирасса",IF($Y$8<=2, $G$25,4),IF(E4="Тяжёлая кирасса, напленики",IF($Y$8<=2, $G$26,4),IF(E4="Киборг",IF($Y$8<=2, $G$27,4),IF(E4="Шлем, лёгкая кирасса, щит",IF($Y$8<=2, $G$28,3),IF(E4="Тяжёлый пехотный доспех",IF($Y$8<=2, $G$29,3),IF(E4="Фелицианский лёгкий бронекостюм",IF($Y$8<=2, $G$30,5),IF(E4="Киборг в лёгкой броне",IF($Y$8<=2, $G$31,3),IF(E4="Бронекостюм",IF($Y$8<=2, $G$32,3),IF(E4="Киборг в тяжёлой броне",IF($Y$8<=2, $G$33,3),IF(E4="Экзоскилет",$G$34,""))))))))))) | K4: =IF(F4="Пистолет",IF(+G4= "Да",$M$37,$G$37),IF(F4="Пистолет-пулемёт",IF(+G4= "Да",$M$37,$G$38),IF(F4="Дробовик",$G$39,IF(F4="Автомат",$G$40,IF(F4="Штурмовой карабин",$G$41,IF(F4="Снайперская Винтовка",$G$42,IF(F4="Пулемёт",$G$43,IF(F4="Гранатомёт/ракетница",$G$44,IF(F4="Противотанокое ружьё",$G$45,IF(F4="Огнемёт",$G$46,IF(F4="ЛазПистолет",IF(+G4= "Да",$M$38, $G$47),IF(F4="ЛазГан",$G$48,IF(F4="ЛазПушка",$G$49,IF(F4="ПлазПистолет ",IF(+G4= "Да",$M$37, $G$50),IF(F4="ПлазГан",$G$51,IF(F4="ПлазПушка",$G$52,IF(F4="Глюонный пистолет",IF(+G4= "Да",$M$37, $G$53),IF(F4="Глюонная винтовка",$G$54,IF(F4="Глюонная пушка",$G$55,""))))))))))))))))))) | L4: =IF(F4="Пистолет",IF(+G4= "Да",$N$37, $H$37),IF(F4="Пистолет-пулемёт",IF(+G4= "Да",$N$38, $H$38),IF(F4="Дробовик",$H$39,IF(F4="Автомат",$H$40,IF(F4="Штурмовой карабин",$H$41,IF(F4="Снайперская Винтовка",$H$42,IF(F4="Пулемёт",$H$43,IF(F4="Гранатомёт/ракетница",$H$44,IF(F4="Противотанокое ружьё",$H$45,IF(F4="Огнемёт",$H$46,IF(F4="ЛазПистолет",IF(+G4= "Да",$N$39, $H$47),IF(F4="ЛазГан",$H$48,IF(F4="ЛазПушка",$H$49,IF(F4="ПлазПистолет ",IF(+G4= "Да",$N$40, $H$50),IF(F4="ПлазГан",$H$51,IF(F4="ПлазПушка",$H$52,IF(F4="Глюонный пистолет",IF(+G4= "Да",$N$41, $H$53),IF(F4="Глюонная винтовка",$H$54,IF(F4="Глюонная пушка",$H$55,""))))))))))))))))))) | M4: Рм | N4: =IF(H4="Без оружия",IF(C4="Мутант",4,IF(E4="Экзоскилет",3,IF(D4="Элитный тяжёлый отряд",3,IF(D4="Спецназ",3,IF(C4="Клон",3,$I$64))))),IF(H4="Нож",IF(C4="Мутант",4,IF(E4="Экзоскилет",4,IF(D4="Элитный тяжёлый отряд",4,IF(D4="Спецназ",4,IF(C4="Клон",3,$I$65))))),IF(H4="Холодное оружие",IF(C4="Мутант",6,IF(E4="Экзоскилет",5,IF(D4="Элитный тяжёлый отряд",5,IF(D4="Спецназ",5,IF(C4="Клон",5,$I$66))))),IF(H4="Пило/Электро",IF(C4="Мутант",7,IF(E4="Экзоскилет",6,IF(D4="Элитный тяжёлый отряд",6,IF(D4="Спецназ",7,IF(C4="Клон",6,$I$67))))),IF(H4="Двуручное оружие ББ",IF(E4="Экзоскилет",7,IF(D4="Элитный тяжёлый отряд",7,IF(D4="Спецназ",7,IF(C4="Клон",7,IF(C4="Мутант",7,$I$68))))),IF(H4="Тяжёлое стрелковое",IF(E4="Экзоскилет",3,$I$69),"")))))) -> 2 | O4: =IF(E4="Одежда",IF(C4="Мутант",3,$F$24),IF(E4="Шлем, лёгкая кирасса",IF(C4="Мутант",4,$F$25),IF(E4="Тяжёлая кирасса, напленики",IF(C4="Мутант",5,$F$26),IF(E4="Киборг",$F$27,IF(E4="Шлем, лёгкая кирасса, щит",IF(C4="Мутант",6,$F$28),IF(E4="Тяжёлый пехотный доспех",IF(C4="Мутант",6,$F$29),IF(E4="Фелицианский лёгкий бронекостюм",$F$30,IF(E4="Киборг в лёгкой броне",$F$31,IF(E4="Бронекостюм",IF(C4="Мутант",6,$F$32),IF(E4="Киборг в тяжёлой броне",$F$33,IF(E4="Экзоскилет",$F$34,""))))))))))) | P4: =IF(D4="Элитный тяжёлый отряд",$F$17,IF(D4="Спецназ",$F$18,IF(D4="Ударное подразделение",$F$19,IF(D4="Основное подразделение",$F$20,IF(D4="Ополчение/Полиция",$F$21,""))))) | Q4: =IF(F4="Пистолет",$K$37,IF(F4="Пистолет-пулемёт",$K$38,IF(F4="Дробовик",$K$39,IF(F4="Автомат",$K$40,IF(F4="Штурмовой карабин",$K$41,IF(F4="Снайперская Винтовка",$K$42,IF(F4="Пулемёт",$K$43,IF(F4="Гранатомёт/ракетница",$K$44,IF(F4="Противотанокое ружьё",$K$45,IF(F4="Огнемёт",$K$46,IF(F4="ЛазПистолет",$K$47,IF(F4="ЛазГан",$K$48,IF(F4="ЛазПушка",$K$49,IF(F4="ПлазПистолет ",$K$50,IF(F4="ПлазГан",$K$51,IF(F4="ПлазПушка",$K$52,IF(F4="Глюонный пистолет",$K$53,IF(F4="Глюонная винтовка",$K$54,IF(F4="Глюонная пушка",$K$55,""))))))))))))))))))) | R4: =IF(H4="Без оружия",$J$64,IF(H4="Нож",$J$65,IF(H4="Холодное оружие",$J$66,IF(H4="Пило/Электро",$J$67,IF(H4="Двуручное оружие ББ",$J$68,IF(H4="Тяжёлое стрелковое",$J$69,"")))))) -> 0 | S4: =IF(M4="(нет)",$N$15,IF(M4="Рм",$N$11,IF(M4="Пр3",$N$12,IF(M4="Пр4",$N$13,IF(M4="Пр5",$N$14,""))))) -> 10 | T4: =IF(E4="Одежда",$H$24,IF(E4="Шлем, лёгкая кирасса",$H$25,IF(E4="Тяжёлая кирасса, напленики",$H$26,IF(E4="Киборг",$H$27,IF(E4="Шлем, лёгкая кирасса, щит",$H$28,IF(E4="Тяжёлый пехотный доспех",$H$29,IF(E4="Фелицианский лёгкий бронекостюм",$H$30,IF(E4="Киборг в лёгкой броне",$H$31,IF(E4="Бронекостюм",$H$32,IF(E4="Киборг в тяжёлой броне",$H$33,IF(E4="Экзоскилет",$H$34,""))))))))))) | U4: =IF(C4="Человек",$H$11,IF(C4="Клон",$H$12,IF(C4="Киборг",$H$13,IF(C4="Мутант",$H$14,"")))) | V4: =SUM(P4:U4) -> 10 | Y4: =IF(F4="Пистолет",0,IF(F4="Пистолет-пулемёт",0,IF(F4="Дробовик",0,IF(F4="Автомат",0,IF(F4="Штурмовой карабин",0,IF(F4="Снайперская Винтовка",1,IF(F4="Пулемёт",1,IF(F4="Гранатомёт/ракетница",1,IF(F4="Противотанокое ружьё",1,IF(F4="Огнемёт",1,IF(F4="ЛазПистолет",0,IF(F4="ЛазГан",0,IF(F4="ЛазПушка",1,IF(F4="ПлазПистолет ",0,IF(F4="ПлазГан",0,IF(F4="ПлазПушка",1,IF(F4="Глюонный пистолет",0,IF(F4="Глюонная винтовка",0,IF(F4="Глюонная пушка",1,"")))))))))))))))))))
B5: 4 | F5: (нет) | H5: Без оружия | I5: =IF(D5="Элитный тяжёлый отряд",IF(C5="Клон",4,$E$17),IF(D5="Спецназ",IF(C5="Клон",3,$E$18),IF(D5="Ударное подразделение",IF(C5="Клон",2,$E$19),IF(D5="Основное подразделение",$E$20,IF(D5="Ополчение/Полиция",$E$21,""))))) | J5: =IF(E5="Одежда",IF($Y$8<=2, $G$24,4),IF(E5="Шлем, лёгкая кирасса",IF($Y$8<=2, $G$25,4),IF(E5="Тяжёлая кирасса, напленики",IF($Y$8<=2, $G$26,4),IF(E5="Киборг",IF($Y$8<=2, $G$27,4),IF(E5="Шлем, лёгкая кирасса, щит",IF($Y$8<=2, $G$28,3),IF(E5="Тяжёлый пехотный доспех",IF($Y$8<=2, $G$29,3),IF(E5="Фелицианский лёгкий бронекостюм",IF($Y$8<=2, $G$30,5),IF(E5="Киборг в лёгкой броне",IF($Y$8<=2, $G$31,3),IF(E5="Бронекостюм",IF($Y$8<=2, $G$32,3),IF(E5="Киборг в тяжёлой броне",IF($Y$8<=2, $G$33,3),IF(E5="Экзоскилет",$G$34,""))))))))))) | K5: =IF(F5="Пистолет",IF(+G5= "Да",$M$37,$G$37),IF(F5="Пистолет-пулемёт",IF(+G5= "Да",$M$37,$G$38),IF(F5="Дробовик",$G$39,IF(F5="Автомат",$G$40,IF(F5="Штурмовой карабин",$G$41,IF(F5="Снайперская Винтовка",$G$42,IF(F5="Пулемёт",$G$43,IF(F5="Гранатомёт/ракетница",$G$44,IF(F5="Противотанокое ружьё",$G$45,IF(F5="Огнемёт",$G$46,IF(F5="ЛазПистолет",IF(+G5= "Да",$M$38, $G$47),IF(F5="ЛазГан",$G$48,IF(F5="ЛазПушка",$G$49,IF(F5="ПлазПистолет ",IF(+G5= "Да",$M$37, $G$50),IF(F5="ПлазГан",$G$51,IF(F5="ПлазПушка",$G$52,IF(F5="Глюонный пистолет",IF(+G5= "Да",$M$37, $G$53),IF(F5="Глюонная винтовка",$G$54,IF(F5="Глюонная пушка",$G$55,""))))))))))))))))))) | L5: =IF(F5="Пистолет",IF(+G5= "Да",$N$37, $H$37),IF(F5="Пистолет-пулемёт",IF(+G5= "Да",$N$38, $H$38),IF(F5="Дробовик",$H$39,IF(F5="Автомат",$H$40,IF(F5="Штурмовой карабин",$H$41,IF(F5="Снайперская Винтовка",$H$42,IF(F5="Пулемёт",$H$43,IF(F5="Гранатомёт/ракетница",$H$44,IF(F5="Противотанокое ружьё",$H$45,IF(F5="Огнемёт",$H$46,IF(F5="ЛазПистолет",IF(+G5= "Да",$N$39, $H$47),IF(F5="ЛазГан",$H$48,IF(F5="ЛазПушка",$H$49,IF(F5="ПлазПистолет ",IF(+G5= "Да",$N$40, $H$50),IF(F5="ПлазГан",$H$51,IF(F5="ПлазПушка",$H$52,IF(F5="Глюонный пистолет",IF(+G5= "Да",$N$41, $H$53),IF(F5="Глюонная винтовка",$H$54,IF(F5="Глюонная пушка",$H$55,""))))))))))))))))))) | M5: (нет) | N5: =IF(H5="Без оружия",IF(C5="Мутант",4,IF(E5="Экзоскилет",3,IF(D5="Элитный тяжёлый отряд",3,IF(D5="Спецназ",3,IF(C5="Клон",3,$I$64))))),IF(H5="Нож",IF(C5="Мутант",4,IF(E5="Экзоскилет",4,IF(D5="Элитный тяжёлый отряд",4,IF(D5="Спецназ",4,IF(C5="Клон",3,$I$65))))),IF(H5="Холодное оружие",IF(C5="Мутант",6,IF(E5="Экзоскилет",5,IF(D5="Элитный тяжёлый отряд",5,IF(D5="Спецназ",5,IF(C5="Клон",5,$I$66))))),IF(H5="Пило/Электро",IF(C5="Мутант",7,IF(E5="Экзоскилет",6,IF(D5="Элитный тяжёлый отряд",6,IF(D5="Спецназ",7,IF(C5="Клон",6,$I$67))))),IF(H5="Двуручное оружие ББ",IF(E5="Экзоскилет",7,IF(D5="Элитный тяжёлый отряд",7,IF(D5="Спецназ",7,IF(C5="Клон",7,IF(C5="Мутант",7,$I$68))))),IF(H5="Тяжёлое стрелковое",IF(E5="Экзоскилет",3,$I$69),"")))))) -> 2 | O5: =IF(E5="Одежда",IF(C5="Мутант",3,$F$24),IF(E5="Шлем, лёгкая кирасса",IF(C5="Мутант",4,$F$25),IF(E5="Тяжёлая кирасса, напленики",IF(C5="Мутант",5,$F$26),IF(E5="Киборг",$F$27,IF(E5="Шлем, лёгкая кирасса, щит",IF(C5="Мутант",6,$F$28),IF(E5="Тяжёлый пехотный доспех",IF(C5="Мутант",6,$F$29),IF(E5="Фелицианский лёгкий бронекостюм",$F$30,IF(E5="Киборг в лёгкой броне",$F$31,IF(E5="Бронекостюм",IF(C5="Мутант",6,$F$32),IF(E5="Киборг в тяжёлой броне",$F$33,IF(E5="Экзоскилет",$F$34,""))))))))))) | P5: =IF(D5="Элитный тяжёлый отряд",$F$17,IF(D5="Спецназ",$F$18,IF(D5="Ударное подразделение",$F$19,IF(D5="Основное подразделение",$F$20,IF(D5="Ополчение/Полиция",$F$21,""))))) | Q5: =IF(F5="Пистолет",$K$37,IF(F5="Пистолет-пулемёт",$K$38,IF(F5="Дробовик",$K$39,IF(F5="Автомат",$K$40,IF(F5="Штурмовой карабин",$K$41,IF(F5="Снайперская Винтовка",$K$42,IF(F5="Пулемёт",$K$43,IF(F5="Гранатомёт/ракетница",$K$44,IF(F5="Противотанокое ружьё",$K$45,IF(F5="Огнемёт",$K$46,IF(F5="ЛазПистолет",$K$47,IF(F5="ЛазГан",$K$48,IF(F5="ЛазПушка",$K$49,IF(F5="ПлазПистолет ",$K$50,IF(F5="ПлазГан",$K$51,IF(F5="ПлазПушка",$K$52,IF(F5="Глюонный пистолет",$K$53,IF(F5="Глюонная винтовка",$K$54,IF(F5="Глюонная пушка",$K$55,""))))))))))))))))))) | R5: =IF(H5="Без оружия",$J$64,IF(H5="Нож",$J$65,IF(H5="Холодное оружие",$J$66,IF(H5="Пило/Электро",$J$67,IF(H5="Двуручное оружие ББ",$J$68,IF(H5="Тяжёлое стрелковое",$J$69,"")))))) -> 0 | S5: =IF(M5="(нет)",$N$15,IF(M5="Рм",$N$11,IF(M5="Пр3",$N$12,IF(M5="Пр4",$N$13,IF(M5="Пр5",$N$14,""))))) -> 0 | T5: =IF(E5="Одежда",$H$24,IF(E5="Шлем, лёгкая кирасса",$H$25,IF(E5="Тяжёлая кирасса, напленики",$H$26,IF(E5="Киборг",$H$27,IF(E5="Шлем, лёгкая кирасса, щит",$H$28,IF(E5="Тяжёлый пехотный доспех",$H$29,IF(E5="Фелицианский лёгкий бронекостюм",$H$30,IF(E5="Киборг в лёгкой броне",$H$31,IF(E5="Бронекостюм",$H$32,IF(E5="Киборг в тяжёлой броне",$H$33,IF(E5="Экзоскилет",$H$34,""))))))))))) | U5: =IF(C5="Человек",$H$11,IF(C5="Клон",$H$12,IF(C5="Киборг",$H$13,IF(C5="Мутант",$H$14,"")))) | V5: =SUM(P5:U5) -> 0 | Y5: =IF(F5="Пистолет",0,IF(F5="Пистолет-пулемёт",0,IF(F5="Дробовик",0,IF(F5="Автомат",0,IF(F5="Штурмовой карабин",0,IF(F5="Снайперская Винтовка",1,IF(F5="Пулемёт",1,IF(F5="Гранатомёт/ракетница",1,IF(F5="Противотанокое ружьё",1,IF(F5="Огнемёт",1,IF(F5="ЛазПистолет",0,IF(F5="ЛазГан",0,IF(F5="ЛазПушка",1,IF(F5="ПлазПистолет ",0,IF(F5="ПлазГан",0,IF(F5="ПлазПушка",1,IF(F5="Глюонный пистолет",0,IF(F5="Глюонная винтовка",0,IF(F5="Глюонная пушка",1,"")))))))))))))))))))
B6: 5 | F6: (нет) | H6: Без оружия | I6: =IF(D6="Элитный тяжёлый отряд",IF(C6="Клон",4,$E$17),IF(D6="Спецназ",IF(C6="Клон",3,$E$18),IF(D6="Ударное подразделение",IF(C6="Клон",2,$E$19),IF(D6="Основное подразделение",$E$20,IF(D6="Ополчение/Полиция",$E$21,""))))) | J6: =IF(E6="Одежда",IF($Y$8<=2, $G$24,4),IF(E6="Шлем, лёгкая кирасса",IF($Y$8<=2, $G$25,4),IF(E6="Тяжёлая кирасса, напленики",IF($Y$8<=2, $G$26,4),IF(E6="Киборг",IF($Y$8<=2, $G$27,4),IF(E6="Шлем, лёгкая кирасса, щит",IF($Y$8<=2, $G$28,3),IF(E6="Тяжёлый пехотный доспех",IF($Y$8<=2, $G$29,3),IF(E6="Фелицианский лёгкий бронекостюм",IF($Y$8<=2, $G$30,5),IF(E6="Киборг в лёгкой броне",IF($Y$8<=2, $G$31,3),IF(E6="Бронекостюм",IF($Y$8<=2, $G$32,3),IF(E6="Киборг в тяжёлой броне",IF($Y$8<=2, $G$33,3),IF(E6="Экзоскилет",$G$34,""))))))))))) | K6: =IF(F6="Пистолет",IF(+G6= "Да",$M$37,$G$37),IF(F6="Пистолет-пулемёт",IF(+G6= "Да",$M$37,$G$38),IF(F6="Дробовик",$G$39,IF(F6="Автомат",$G$40,IF(F6="Штурмовой карабин",$G$41,IF(F6="Снайперская Винтовка",$G$42,IF(F6="Пулемёт",$G$43,IF(F6="Гранатомёт/ракетница",$G$44,IF(F6="Противотанокое ружьё",$G$45,IF(F6="Огнемёт",$G$46,IF(F6="ЛазПистолет",IF(+G6= "Да",$M$38, $G$47),IF(F6="ЛазГан",$G$48,IF(F6="ЛазПушка",$G$49,IF(F6="ПлазПистолет ",IF(+G6= "Да",$M$37, $G$50),IF(F6="ПлазГан",$G$51,IF(F6="ПлазПушка",$G$52,IF(F6="Глюонный пистолет",IF(+G6= "Да",$M$37, $G$53),IF(F6="Глюонная винтовка",$G$54,IF(F6="Глюонная пушка",$G$55,""))))))))))))))))))) | L6: =IF(F6="Пистолет",IF(+G6= "Да",$N$37, $H$37),IF(F6="Пистолет-пулемёт",IF(+G6= "Да",$N$38, $H$38),IF(F6="Дробовик",$H$39,IF(F6="Автомат",$H$40,IF(F6="Штурмовой карабин",$H$41,IF(F6="Снайперская Винтовка",$H$42,IF(F6="Пулемёт",$H$43,IF(F6="Гранатомёт/ракетница",$H$44,IF(F6="Противотанокое ружьё",$H$45,IF(F6="Огнемёт",$H$46,IF(F6="ЛазПистолет",IF(+G6= "Да",$N$39, $H$47),IF(F6="ЛазГан",$H$48,IF(F6="ЛазПушка",$H$49,IF(F6="ПлазПистолет ",IF(+G6= "Да",$N$40, $H$50),IF(F6="ПлазГан",$H$51,IF(F6="ПлазПушка",$H$52,IF(F6="Глюонный пистолет",IF(+G6= "Да",$N$41, $H$53),IF(F6="Глюонная винтовка",$H$54,IF(F6="Глюонная пушка",$H$55,""))))))))))))))))))) | M6: (нет) | N6: =IF(H6="Без оружия",IF(C6="Мутант",4,IF(E6="Экзоскилет",3,IF(D6="Элитный тяжёлый отряд",3,IF(D6="Спецназ",3,IF(C6="Клон",3,$I$64))))),IF(H6="Нож",IF(C6="Мутант",4,IF(E6="Экзоскилет",4,IF(D6="Элитный тяжёлый отряд",4,IF(D6="Спецназ",4,IF(C6="Клон",3,$I$65))))),IF(H6="Холодное оружие",IF(C6="Мутант",6,IF(E6="Экзоскилет",5,IF(D6="Элитный тяжёлый отряд",5,IF(D6="Спецназ",5,IF(C6="Клон",5,$I$66))))),IF(H6="Пило/Электро",IF(C6="Мутант",7,IF(E6="Экзоскилет",6,IF(D6="Элитный тяжёлый отряд",6,IF(D6="Спецназ",7,IF(C6="Клон",6,$I$67))))),IF(H6="Двуручное оружие ББ",IF(E6="Экзоскилет",7,IF(D6="Элитный тяжёлый отряд",7,IF(D6="Спецназ",7,IF(C6="Клон",7,IF(C6="Мутант",7,$I$68))))),IF(H6="Тяжёлое стрелковое",IF(E6="Экзоскилет",3,$I$69),"")))))) -> 2 | O6: =IF(E6="Одежда",IF(C6="Мутант",3,$F$24),IF(E6="Шлем, лёгкая кирасса",IF(C6="Мутант",4,$F$25),IF(E6="Тяжёлая кирасса, напленики",IF(C6="Мутант",5,$F$26),IF(E6="Киборг",$F$27,IF(E6="Шлем, лёгкая кирасса, щит",IF(C6="Мутант",6,$F$28),IF(E6="Тяжёлый пехотный доспех",IF(C6="Мутант",6,$F$29),IF(E6="Фелицианский лёгкий бронекостюм",$F$30,IF(E6="Киборг в лёгкой броне",$F$31,IF(E6="Бронекостюм",IF(C6="Мутант",6,$F$32),IF(E6="Киборг в тяжёлой броне",$F$33,IF(E6="Экзоскилет",$F$34,""))))))))))) | P6: =IF(D6="Элитный тяжёлый отряд",$F$17,IF(D6="Спецназ",$F$18,IF(D6="Ударное подразделение",$F$19,IF(D6="Основное подразделение",$F$20,IF(D6="Ополчение/Полиция",$F$21,""))))) | Q6: =IF(F6="Пистолет",$K$37,IF(F6="Пистолет-пулемёт",$K$38,IF(F6="Дробовик",$K$39,IF(F6="Автомат",$K$40,IF(F6="Штурмовой карабин",$K$41,IF(F6="Снайперская Винтовка",$K$42,IF(F6="Пулемёт",$K$43,IF(F6="Гранатомёт/ракетница",$K$44,IF(F6="Противотанокое ружьё",$K$45,IF(F6="Огнемёт",$K$46,IF(F6="ЛазПистолет",$K$47,IF(F6="ЛазГан",$K$48,IF(F6="ЛазПушка",$K$49,IF(F6="ПлазПистолет ",$K$50,IF(F6="ПлазГан",$K$51,IF(F6="ПлазПушка",$K$52,IF(F6="Глюонный пистолет",$K$53,IF(F6="Глюонная винтовка",$K$54,IF(F6="Глюонная пушка",$K$55,""))))))))))))))))))) | R6: =IF(H6="Без оружия",$J$64,IF(H6="Нож",$J$65,IF(H6="Холодное оружие",$J$66,IF(H6="Пило/Электро",$J$67,IF(H6="Двуручное оружие ББ",$J$68,IF(H6="Тяжёлое стрелковое",$J$69,"")))))) -> 0 | S6: =IF(M6="(нет)",$N$15,IF(M6="Рм",$N$11,IF(M6="Пр3",$N$12,IF(M6="Пр4",$N$13,IF(M6="Пр5",$N$14,""))))) -> 0 | T6: =IF(E6="Одежда",$H$24,IF(E6="Шлем, лёгкая кирасса",$H$25,IF(E6="Тяжёлая кирасса, напленики",$H$26,IF(E6="Киборг",$H$27,IF(E6="Шлем, лёгкая кирасса, щит",$H$28,IF(E6="Тяжёлый пехотный доспех",$H$29,IF(E6="Фелицианский лёгкий бронекостюм",$H$30,IF(E6="Киборг в лёгкой броне",$H$31,IF(E6="Бронекостюм",$H$32,IF(E6="Киборг в тяжёлой броне",$H$33,IF(E6="Экзоскилет",$H$34,""))))))))))) | U6: =IF(C6="Человек",$H$11,IF(C6="Клон",$H$12,IF(C6="Киборг",$H$13,IF(C6="Мутант",$H$14,"")))) | V6: =SUM(P6:U6) -> 0 | Y6: =IF(F6="Пистолет",0,IF(F6="Пистолет-пулемёт",0,IF(F6="Дробовик",0,IF(F6="Автомат",0,IF(F6="Штурмовой карабин",0,IF(F6="Снайперская Винтовка",1,IF(F6="Пулемёт",1,IF(F6="Гранатомёт/ракетница",1,IF(F6="Противотанокое ружьё",1,IF(F6="Огнемёт",1,IF(F6="ЛазПистолет",0,IF(F6="ЛазГан",0,IF(F6="ЛазПушка",1,IF(F6="ПлазПистолет ",0,IF(F6="ПлазГан",0,IF(F6="ПлазПушка",1,IF(F6="Глюонный пистолет",0,IF(F6="Глюонная винтовка",0,IF(F6="Глюонная пушка",1,"")))))))))))))))))))
B7: 6 | F7: (нет) | H7: Без оружия | I7: =IF(D7="Элитный тяжёлый отряд",IF(C7="Клон",4,$E$17),IF(D7="Спецназ",IF(C7="Клон",3,$E$18),IF(D7="Ударное подразделение",IF(C7="Клон",2,$E$19),IF(D7="Основное подразделение",$E$20,IF(D7="Ополчение/Полиция",$E$21,""))))) | J7: =IF(E7="Одежда",IF($Y$8<=2, $G$24,4),IF(E7="Шлем, лёгкая кирасса",IF($Y$8<=2, $G$25,4),IF(E7="Тяжёлая кирасса, напленики",IF($Y$8<=2, $G$26,4),IF(E7="Киборг",IF($Y$8<=2, $G$27,4),IF(E7="Шлем, лёгкая кирасса, щит",IF($Y$8<=2, $G$28,3),IF(E7="Тяжёлый пехотный доспех",IF($Y$8<=2, $G$29,3),IF(E7="Фелицианский лёгкий бронекостюм",IF($Y$8<=2, $G$30,5),IF(E7="Киборг в лёгкой броне",IF($Y$8<=2, $G$31,3),IF(E7="Бронекостюм",IF($Y$8<=2, $G$32,3),IF(E7="Киборг в тяжёлой броне",IF($Y$8<=2, $G$33,3),IF(E7="Экзоскилет",$G$34,""))))))))))) | K7: =IF(F7="Пистолет",IF(+G7= "Да",$M$37,$G$37),IF(F7="Пистолет-пулемёт",IF(+G7= "Да",$M$37,$G$38),IF(F7="Дробовик",$G$39,IF(F7="Автомат",$G$40,IF(F7="Штурмовой карабин",$G$41,IF(F7="Снайперская Винтовка",$G$42,IF(F7="Пулемёт",$G$43,IF(F7="Гранатомёт/ракетница",$G$44,IF(F7="Противотанокое ружьё",$G$45,IF(F7="Огнемёт",$G$46,IF(F7="ЛазПистолет",IF(+G7= "Да",$M$38, $G$47),IF(F7="ЛазГан",$G$48,IF(F7="ЛазПушка",$G$49,IF(F7="ПлазПистолет ",IF(+G7= "Да",$M$37, $G$50),IF(F7="ПлазГан",$G$51,IF(F7="ПлазПушка",$G$52,IF(F7="Глюонный пистолет",IF(+G7= "Да",$M$37, $G$53),IF(F7="Глюонная винтовка",$G$54,IF(F7="Глюонная пушка",$G$55,""))))))))))))))))))) | L7: =IF(F7="Пистолет",IF(+G7= "Да",$N$37, $H$37),IF(F7="Пистолет-пулемёт",IF(+G7= "Да",$N$38, $H$38),IF(F7="Дробовик",$H$39,IF(F7="Автомат",$H$40,IF(F7="Штурмовой карабин",$H$41,IF(F7="Снайперская Винтовка",$H$42,IF(F7="Пулемёт",$H$43,IF(F7="Гранатомёт/ракетница",$H$44,IF(F7="Противотанокое ружьё",$H$45,IF(F7="Огнемёт",$H$46,IF(F7="ЛазПистолет",IF(+G7= "Да",$N$39, $H$47),IF(F7="ЛазГан",$H$48,IF(F7="ЛазПушка",$H$49,IF(F7="ПлазПистолет ",IF(+G7= "Да",$N$40, $H$50),IF(F7="ПлазГан",$H$51,IF(F7="ПлазПушка",$H$52,IF(F7="Глюонный пистолет",IF(+G7= "Да",$N$41, $H$53),IF(F7="Глюонная винтовка",$H$54,IF(F7="Глюонная пушка",$H$55,""))))))))))))))))))) | M7: (нет) | N7: =IF(H7="Без оружия",IF(C7="Мутант",4,IF(E7="Экзоскилет",3,IF(D7="Элитный тяжёлый отряд",3,IF(D7="Спецназ",3,IF(C7="Клон",3,$I$64))))),IF(H7="Нож",IF(C7="Мутант",4,IF(E7="Экзоскилет",4,IF(D7="Элитный тяжёлый отряд",4,IF(D7="Спецназ",4,IF(C7="Клон",3,$I$65))))),IF(H7="Холодное оружие",IF(C7="Мутант",6,IF(E7="Экзоскилет",5,IF(D7="Элитный тяжёлый отряд",5,IF(D7="Спецназ",5,IF(C7="Клон",5,$I$66))))),IF(H7="Пило/Электро",IF(C7="Мутант",7,IF(E7="Экзоскилет",6,IF(D7="Элитный тяжёлый отряд",6,IF(D7="Спецназ",7,IF(C7="Клон",6,$I$67))))),IF(H7="Двуручное оружие ББ",IF(E7="Экзоскилет",7,IF(D7="Элитный тяжёлый отряд",7,IF(D7="Спецназ",7,IF(C7="Клон",7,IF(C7="Мутант",7,$I$68))))),IF(H7="Тяжёлое стрелковое",IF(E7="Экзоскилет",3,$I$69),"")))))) -> 2 | O7: =IF(E7="Одежда",IF(C7="Мутант",3,$F$24),IF(E7="Шлем, лёгкая кирасса",IF(C7="Мутант",4,$F$25),IF(E7="Тяжёлая кирасса, напленики",IF(C7="Мутант",5,$F$26),IF(E7="Киборг",$F$27,IF(E7="Шлем, лёгкая кирасса, щит",IF(C7="Мутант",6,$F$28),IF(E7="Тяжёлый пехотный доспех",IF(C7="Мутант",6,$F$29),IF(E7="Фелицианский лёгкий бронекостюм",$F$30,IF(E7="Киборг в лёгкой броне",$F$31,IF(E7="Бронекостюм",IF(C7="Мутант",6,$F$32),IF(E7="Киборг в тяжёлой броне",$F$33,IF(E7="Экзоскилет",$F$34,""))))))))))) | P7: =IF(D7="Элитный тяжёлый отряд",$F$17,IF(D7="Спецназ",$F$18,IF(D7="Ударное подразделение",$F$19,IF(D7="Основное подразделение",$F$20,IF(D7="Ополчение/Полиция",$F$21,""))))) | Q7: =IF(F7="Пистолет",$K$37,IF(F7="Пистолет-пулемёт",$K$38,IF(F7="Дробовик",$K$39,IF(F7="Автомат",$K$40,IF(F7="Штурмовой карабин",$K$41,IF(F7="Снайперская Винтовка",$K$42,IF(F7="Пулемёт",$K$43,IF(F7="Гранатомёт/ракетница",$K$44,IF(F7="Противотанокое ружьё",$K$45,IF(F7="Огнемёт",$K$46,IF(F7="ЛазПистолет",$K$47,IF(F7="ЛазГан",$K$48,IF(F7="ЛазПушка",$K$49,IF(F7="ПлазПистолет ",$K$50,IF(F7="ПлазГан",$K$51,IF(F7="ПлазПушка",$K$52,IF(F7="Глюонный пистолет",$K$53,IF(F7="Глюонная винтовка",$K$54,IF(F7="Глюонная пушка",$K$55,""))))))))))))))))))) | R7: =IF(H7="Без оружия",$J$64,IF(H7="Нож",$J$65,IF(H7="Холодное оружие",$J$66,IF(H7="Пило/Электро",$J$67,IF(H7="Двуручное оружие ББ",$J$68,IF(H7="Тяжёлое стрелковое",$J$69,"")))))) -> 0 | S7: =IF(M7="(нет)",$N$15,IF(M7="Рм",$N$11,IF(M7="Пр3",$N$12,IF(M7="Пр4",$N$13,IF(M7="Пр5",$N$14,""))))) -> 0 | T7: =IF(E7="Одежда",$H$24,IF(E7="Шлем, лёгкая кирасса",$H$25,IF(E7="Тяжёлая кирасса, напленики",$H$26,IF(E7="Киборг",$H$27,IF(E7="Шлем, лёгкая кирасса, щит",$H$28,IF(E7="Тяжёлый пехотный доспех",$H$29,IF(E7="Фелицианский лёгкий бронекостюм",$H$30,IF(E7="Киборг в лёгкой броне",$H$31,IF(E7="Бронекостюм",$H$32,IF(E7="Киборг в тяжёлой броне",$H$33,IF(E7="Экзоскилет",$H$34,""))))))))))) | U7: =IF(C7="Человек",$H$11,IF(C7="Клон",$H$12,IF(C7="Киборг",$H$13,IF(C7="Мутант",$H$14,"")))) | V7: =SUM(P7:U7) -> 0 | Y7: =IF(F7="Пистолет",0,IF(F7="Пистолет-пулемёт",0,IF(F7="Дробовик",0,IF(F7="Автомат",0,IF(F7="Штурмовой карабин",0,IF(F7="Снайперская Винтовка",1,IF(F7="Пулемёт",1,IF(F7="Гранатомёт/ракетница",1,IF(F7="Противотанокое ружьё",1,IF(F7="Огнемёт",1,IF(F7="ЛазПистолет",0,IF(F7="ЛазГан",0,IF(F7="ЛазПушка",1,IF(F7="ПлазПистолет ",0,IF(F7="ПлазГан",0,IF(F7="ПлазПушка",1,IF(F7="Глюонный пистолет",0,IF(F7="Глюонная винтовка",0,IF(F7="Глюонная пушка",1,"")))))))))))))))))))
N8: =IF(H8="Без оружия",IF(C8="Мутант",4, IF(E8="Экзоскилет",3, IF(D8="Элитный тяжёлый отряд",3,IF(D8="Спецназ",3, IF(C8="Клон",3, $I$64))))),IF(H8="Приклад",IF(C8="Мутант",4,IF(E8="Экзоскилет",4, IF(D8="Элитный тяжёлый отряд",4,IF(D8="Спецназ",4, IF(C8="Клон",3, $I$64))))),IF(H8="Нож",IF(C8="Мутант",4,IF(E8="Экзоскилет",4, IF(D8="Элитный тяжёлый отряд",4,IF(D8="Спецназ",4, IF(C8="Клон",3, $I$65))))),IF(H8="Холодное оружие",IF(C8="Мутант",6, IF(E8="Экзоскилет",5, IF(D8="Элитный тяжёлый отряд",5,IF(D8="Спецназ",5, IF(C8="Клон",5, $I$66))))),IF(H8="Пило/Электро",IF(C8="Мутант",7, IF(E8="Экзоскилет",6, IF(D8="Элитный тяжёлый отряд",6,IF(D8="Спецназ",7, IF(C8="Клон",6, $I$67))))),IF(H8="Двуручное оружие ББ",IF(E8="Экзоскилет",7, IF(D8="Элитный тяжёлый отряд",7,IF(D8="Спецназ",7, IF(C8="Клон",7, IF(C8="Мутант",7, $I$68))))),IF(H8="Тяжёлое стрелковое",IF(E8="Экзоскилет",3, $I$69),""))))))) | Y8: =SUM(Y2:Y7) -> 0
C10: Наименование | D10: Бонус к АрмРанг | E10: Бонус к сокорости | F10: Бонус к броне | G10: Бонус к ББ | H10: ЦЕНА | M10: Свойство | N10: Цена
C11: Человек | D11: 0 | E11: 0 | F11: 0 | G11: 0 | H11: 20 | M11: Рм | N11: 10
C12: Клон | D12: -1 | E12: 0 | F12: 0 | G12: 1 | H12: 10 | M12: Пр3 | N12: 20
C13: Киборг | D13: 0 | E13: 0 | F13: 1 | G13: 0 | H13: 30 | M13: Пр4 | N13: 30
C14: Мутант | D14: 0 | E14: 0 | F14: 2 | G14: 2 | H14: 40 | M14: Пр5 | N14: 40
M15: (нет) | N15: 0
D16: Тип отряда | E16: АрмРанг | F16: Цена
D17: Элитный тяжёлый отряд | E17: 5 | F17: 50
D18: Спецназ | E18: 4 | F18: 30
D19: Ударное подразделение | E19: 3 | F19: 20
D20: Основное подразделение | E20: 2 | F20: 15
D21: Ополчение/Полиция | E21: 1 | F21: 5
E23: Вид: | F23: Броня | G23: Скорость | H23: Цена
E24: Одежда | F24: 1 | G24: 5 | H24: 0 | Q24: =IF(Y8<2,"","")
E25: Шлем, лёгкая кирасса | F25: 2 | G25: 5 | H25: 20
E26: Тяжёлая кирасса, напленики | F26: 3 | G26: 5 | H26: 60
E27: Киборг | F27: 4 | G27: 4 | H27: 90
E28: Шлем, лёгкая кирасса, щит | F28: 4 | G28: 4 | H28: 40
E29: Тяжёлый пехотный доспех | F29: 4 | G29: 4 | H29: 80
E30: Фелицианский лёгкий бронекостюм | F30: 3 | G30: 6 | H30: 100
E31: Киборг в лёгкой броне | F31: 3 | G31: 5 | H31: 30
E32: Бронекостюм | F32: 5 | G32: 4 | H32: 100
E33: Киборг в тяжёлой броне | F33: 5 | G33: 4 | H33: 120
E34: Экзоскилет | F34: 6 | G34: 3 | H34: 140
P35: ПОДБОР ПАРАМЕТРОВ ДЛЯ АВТОМАТИЧЕСКОГО ПОДСЧЁТА | V35: ПОДБОР ПАРАМЕТРОВ ДЛЯ АВТОМАТИЧЕСКОГО ПОДСЧЁТА
B36: Показатель | C36: Цена дальности | D36: Цена мощности | F36: Класс | G36: Дальность | H36: Мощность | I36: Цена дальности | J36: Цена мощности | K36: Цена оружия | M36: Македонец Дальносить | N36: Македонец Мощность | P36: Показатель дальности | Q36: Модификатор дальности | R36: Множитель Дальности | S36: Цена дальности | T36: Цена модификатора | U36: Множитель цены | V36: Показатель мощности | W36: Модификатор мощности | X36: Множитель мощности | Y36: Цена дальности | Z36: Цена модификатора | AA36: Множитель цены
B37: Д6 | C37: 5 | D37: 10 | F37: Пистолет | G37: Д6 | H37: Д6 | I37: =S37*U37+T37 -> 5 | J37: =Y37*AA37+Z37 -> 10 | K37: =J37+I37 -> 15 | M37: Д6-1 | N37: 2Д6 | P37: Д6 | Q37: х | R37: х | S37: =IF(P37="Д6",$C$37,IF(P37="Д12",$C$38,IF(P37="Д20",$C$39,""))) -> 5 | T37: =IF(Q37="х",$D$42,IF(Q37="х+1",$C$43,IF(Q37="х+2",$C$44,IF(Q37="х+3",$C$45,"")))) -> 0 | U37: =IF(R37="х",$C$42,IF(R37="2х",$C$40,IF(R37="3х",$C$41,""))) -> 1 | V37: Д6 | W37: х | X37: х | Y37: =IF(V37="Д6",$D$37,IF(V37="Д12",$D$38,IF(V37="Д20",$D$39,""))) -> 10 | Z37: =IF(W37="х",$D$42,IF(W37="х+1",$D$43,IF(W37="х+2",$D$44,IF(W37="х+3",$D$45,"")))) -> 0 | AA37: =IF(X37="х",$C$42,IF(X37="2х",$D$40,IF(X37="3х",$D$41,""))) -> 1
B38: Д12 | C38: 20 | D38: 40 | F38: Пистолет-пулемёт | G38: Д6 | H38: 2Д6 | I38: =S38*U38+T38 -> 5 | J38: =Y38*AA38+Z38 -> 20 | K38: =J38+I38 -> 25 | M38: 2Д6-1 | N38: 3Д6 | P38: Д6 | Q38: х | R38: х | S38: =IF(P38="Д6",$C$37,IF(P38="Д12",$C$38,IF(P38="Д20",$C$39,""))) -> 5 | T38: =IF(Q38="х",$D$42,IF(Q38="х+1",$C$43,IF(Q38="х+2",$C$44,IF(Q38="х+3",$C$45,"")))) -> 0 | U38: =IF(R38="х",$C$42,IF(R38="2х",$C$40,IF(R38="3х",$C$41,""))) -> 1 | V38: Д6 | W38: х | X38: 2х | Y38: =IF(V38="Д6",$D$37,IF(V38="Д12",$D$38,IF(V38="Д20",$D$39,""))) -> 10 | Z38: =IF(W38="х",$D$42,IF(W38="х+1",$D$43,IF(W38="х+2",$D$44,IF(W38="х+3",$D$45,"")))) -> 0 | AA38: =IF(X38="х",$C$42,IF(X38="2х",$D$40,IF(X38="3х",$D$41,""))) -> 2
B39: Д20 | C39: 40 | D39: 80 | F39: Дробовик | G39: Д6 | H39: 3Д6 | I39: =S39*U39+T39 -> 5 | J39: =Y39*AA39+Z39 -> 30 | K39: =J39+I39 -> 35 | N39: 2Д6+1 | P39: Д6 | Q39: х | R39: х | S39: =IF(P39="Д6",$C$37,IF(P39="Д12",$C$38,IF(P39="Д20",$C$39,""))) -> 5 | T39: =IF(Q39="х",$D$42,IF(Q39="х+1",$C$43,IF(Q39="х+2",$C$44,IF(Q39="х+3",$C$45,"")))) -> 0 | U39: =IF(R39="х",$C$42,IF(R39="2х",$C$40,IF(R39="3х",$C$41,""))) -> 1 | V39: Д6 | W39: х | X39: 3х | Y39: =IF(V39="Д6",$D$37,IF(V39="Д12",$D$38,IF(V39="Д20",$D$39,""))) -> 10 | Z39: =IF(W39="х",$D$42,IF(W39="х+1",$D$43,IF(W39="х+2",$D$44,IF(W39="х+3",$D$45,"")))) -> 0 | AA39: =IF(X39="х",$C$42,IF(X39="2х",$D$40,IF(X39="3х",$D$41,""))) -> 3
A40: умнажить цену на значение | B40: 2х | C40: 2 | D40: 2 | F40: Автомат | G40: Д12 | H40: 2Д6 | I40: =S40*U40+T40 -> 20 | J40: =Y40*AA40+Z40 -> 20 | K40: =J40+I40 -> 40 | N40: 2Д6+3 | P40: Д12 | Q40: х | R40: х | S40: =IF(P40="Д6",$C$37,IF(P40="Д12",$C$38,IF(P40="Д20",$C$39,""))) -> 20 | T40: =IF(Q40="х",$D$42,IF(Q40="х+1",$C$43,IF(Q40="х+2",$C$44,IF(Q40="х+3",$C$45,"")))) -> 0 | U40: =IF(R40="х",$C$42,IF(R40="2х",$C$40,IF(R40="3х",$C$41,""))) -> 1 | V40: Д6 | W40: х | X40: 2х | Y40: =IF(V40="Д6",$D$37,IF(V40="Д12",$D$38,IF(V40="Д20",$D$39,""))) -> 10 | Z40: =IF(W40="х",$D$42,IF(W40="х+1",$D$43,IF(W40="х+2",$D$44,IF(W40="х+3",$D$45,"")))) -> 0 | AA40: =IF(X40="х",$C$42,IF(X40="2х",$D$40,IF(X40="3х",$D$41,""))) -> 2
B41: 3х | C41: 3 | D41: 3 | F41: Штурмовой карабин | G41: Д6 | H41: Д12 | I41: =S41*U41+T41 -> 5 | J41: =Y41*AA41+Z41 -> 40 | K41: =J41+I41 -> 45 | N41: 3Д6+3 | P41: Д6 | Q41: х | R41: х | S41: =IF(P41="Д6",$C$37,IF(P41="Д12",$C$38,IF(P41="Д20",$C$39,""))) -> 5 | T41: =IF(Q41="х",$D$42,IF(Q41="х+1",$C$43,IF(Q41="х+2",$C$44,IF(Q41="х+3",$C$45,"")))) -> 0 | U41: =IF(R41="х",$C$42,IF(R41="2х",$C$40,IF(R41="3х",$C$41,""))) -> 1 | V41: Д12 | W41: х | X41: х | Y41: =IF(V41="Д6",$D$37,IF(V41="Д12",$D$38,IF(V41="Д20",$D$39,""))) -> 40 | Z41: =IF(W41="х",$D$42,IF(W41="х+1",$D$43,IF(W41="х+2",$D$44,IF(W41="х+3",$D$45,"")))) -> 0 | AA41: =IF(X41="х",$C$42,IF(X41="2х",$D$40,IF(X41="3х",$D$41,""))) -> 1
A42: не трогать строку | B42: х | C42: 1 | D42: 0 | F42: Снайперская Винтовка | G42: Д12+2 | H42: Д12 | I42: =S42*U42+T42 -> 40 | J42: =Y42*AA42+Z42 -> 40 | K42: =J42+I42 -> 80 | P42: Д12 | Q42: х+2 | R42: х | S42: =IF(P42="Д6",$C$37,IF(P42="Д12",$C$38,IF(P42="Д20",$C$39,""))) -> 20 | T42: =IF(Q42="х",$D$42,IF(Q42="х+1",$C$43,IF(Q42="х+2",$C$44,IF(Q42="х+3",$C$45,"")))) -> 20 | U42: =IF(R42="х",$C$42,IF(R42="2х",$C$40,IF(R42="3х",$C$41,""))) -> 1 | V42: Д12 | W42: х | X42: х | Y42: =IF(V42="Д6",$D$37,IF(V42="Д12",$D$38,IF(V42="Д20",$D$39,""))) -> 40 | Z42: =IF(W42="х",$D$42,IF(W42="х+1",$D$43,IF(W42="х+2",$D$44,IF(W42="х+3",$D$45,"")))) -> 0 | AA42: =IF(X42="х",$C$42,IF(X42="2х",$D$40,IF(X42="3х",$D$41,""))) -> 1
...

Sheet Шаблон армлиста
C3: <Название фракции> | K3: Стоимость | M3: ='АвтоРасчёт '!X2 -> 5
C4: <Название отрядва>
E5: А | F5: Ск | G5: Дальн | H5: Мощн | I5: ББ | J5: Св | K5: Бр
C6: Боец 1 | D6: 1 | E6: ='АвтоРасчёт '!I2 | F6: ='АвтоРасчёт '!J2 | G6: ='АвтоРасчёт '!K2 | H6: ='АвтоРасчёт '!L2 | I6: ='АвтоРасчёт '!N2 -> 2 | J6: ='АвтоРасчёт '!M2 -> (нет) | K6: ='АвтоРасчёт '!O2 | M6: Боец 2
E7: ='АвтоРасчёт '!I3 | F7: ='АвтоРасчёт '!J3 | G7: ='АвтоРасчёт '!K3 | H7: ='АвтоРасчёт '!L3 | I7: ='АвтоРасчёт '!N3 -> 2 | J7: ='АвтоРасчёт '!M3 -> (нет) | K7: ='АвтоРасчёт '!O3 | L7: 2
C8: Боец 3 | D8: 3 | E8: ='АвтоРасчёт '!I4 | F8: ='АвтоРасчёт '!J4 | G8: ='АвтоРасчёт '!K4 | H8: ='АвтоРасчёт '!L4 | I8: ='АвтоРасчёт '!N4 -> 2 | J8: ='АвтоРасчёт '!M4 -> Рм | K8: ='АвтоРасчёт '!O4 | M8: Боец 4
E9: ='АвтоРасчёт '!I5 | F9: ='АвтоРасчёт '!J5 | G9: ='АвтоРасчёт '!K5 | H9: ='АвтоРасчёт '!L5 | I9: ='АвтоРасчёт '!N5 -> 2 | J9: ='АвтоРасчёт '!M5 -> (нет) | K9: ='АвтоРасчёт '!O5 | L9: 4
C10: Боец 5 | D10: 5 | E10: ='АвтоРасчёт '!I6 | F10: ='АвтоРасчёт '!J6 | G10: ='АвтоРасчёт '!K6 | H10: ='АвтоРасчёт '!L6 | I10: ='АвтоРасчёт '!N6 -> 2 | J10: ='АвтоРасчёт '!M6 -> (нет) | K10: ='АвтоРасчёт '!O6 | M10: Боец 6
E11: ='АвтоРасчёт '!I7 | F11: ='АвтоРасчёт '!J7 | G11: ='АвтоРасчёт '!K7 | H11: ='АвтоРасчёт '!L7 | I11: ='АвтоРасчёт '!N7 -> 2 | J11: ='АвтоРасчёт '!M7 -> (нет) | K11: ='АвтоРасчёт '!O7 | L11: 6
G51: Д12
G54: Д12
G55: Д12
